Workbook

Sheet Read me
A1: Shell data platform – access requests for the new DevOps process
A2: Repo: <shell-org>/shell-data-platform · GitHub Actions · Azure Boards · ADF · Databricks Asset Bundles · Azure SQL config DB · Requested by Vamshi Singam
A4: How to use
A5: 1. 'Access requests' has one row per permission. Columns M–P (yellow) are for the admin: set Status, your name, date, comments.
A6: 2. Filter column C ('Granted by') to see only the rows your team owns.
A7: 3. Phase P1 rows block the start of development; P2 rows are needed before the first QA release; P3 before the first PROD release.
A8: 4. 'Names to return' lists the resource names and IDs we need back (yellow cells).
A9: 5. 'Open questions' must be answered first: several rows depend on them (see Notes column).
A10: No passwords or secrets are requested for Azure: GitHub signs in with the existing managed identities through federated credentials.
A12: Summary by owner
A13: Granted by | B13: Total | C13: P1 rows | D13: Granted | E13: Open
A14: GitHub org owner | B14: =COUNTIF('Access requests'!$C$2:$C$48,A14) -> 12 | C14: =COUNTIFS('Access requests'!$C$2:$C$48,A14,'Access requests'!$K$2:$K$48,"P1*") -> 9 | D14: =COUNTIFS('Access requests'!$C$2:$C$48,A14,'Access requests'!$M$2:$M$48,"Granted") -> 0 | E14: =B14-D14-COUNTIFS('Access requests'!$C$2:$C$48,A14,'Access requests'!$M$2:$M$48,"Not needed") -> 12
A15: Entra ID admin / identity owner | B15: =COUNTIF('Access requests'!$C$2:$C$48,A15) -> 6 | C15: =COUNTIFS('Access requests'!$C$2:$C$48,A15,'Access requests'!$K$2:$K$48,"P1*") -> 4 | D15: =COUNTIFS('Access requests'!$C$2:$C$48,A15,'Access requests'!$M$2:$M$48,"Granted") -> 0 | E15: =B15-D15-COUNTIFS('Access requests'!$C$2:$C$48,A15,'Access requests'!$M$2:$M$48,"Not needed") -> 6
A16: Azure subscription owner (RBAC) | B16: =COUNTIF('Access requests'!$C$2:$C$48,A16) -> 8 | C16: =COUNTIFS('Access requests'!$C$2:$C$48,A16,'Access requests'!$K$2:$K$48,"P1*") -> 7 | D16: =COUNTIFS('Access requests'!$C$2:$C$48,A16,'Access requests'!$M$2:$M$48,"Granted") -> 0 | E16: =B16-D16-COUNTIFS('Access requests'!$C$2:$C$48,A16,'Access requests'!$M$2:$M$48,"Not needed") -> 8
A17: Azure SQL server Entra admin | B17: =COUNTIF('Access requests'!$C$2:$C$48,A17) -> 4 | C17: =COUNTIFS('Access requests'!$C$2:$C$48,A17,'Access requests'!$K$2:$K$48,"P1*") -> 4 | D17: =COUNTIFS('Access requests'!$C$2:$C$48,A17,'Access requests'!$M$2:$M$48,"Granted") -> 0 | E17: =B17-D17-COUNTIFS('Access requests'!$C$2:$C$48,A17,'Access requests'!$M$2:$M$48,"Not needed") -> 4
A18: Databricks account admin | B18: =COUNTIF('Access requests'!$C$2:$C$48,A18) -> 1 | C18: =COUNTIFS('Access requests'!$C$2:$C$48,A18,'Access requests'!$K$2:$K$48,"P1*") -> 1 | D18: =COUNTIFS('Access requests'!$C$2:$C$48,A18,'Access requests'!$M$2:$M$48,"Granted") -> 0 | E18: =B18-D18-COUNTIFS('Access requests'!$C$2:$C$48,A18,'Access requests'!$M$2:$M$48,"Not needed") -> 1
A19: Databricks workspace admin / UC catalog owner | B19: =COUNTIF('Access requests'!$C$2:$C$48,A19) -> 8 | C19: =COUNTIFS('Access requests'!$C$2:$C$48,A19,'Access requests'!$K$2:$K$48,"P1*") -> 7 | D19: =COUNTIFS('Access requests'!$C$2:$C$48,A19,'Access requests'!$M$2:$M$48,"Granted") -> 0 | E19: =B19-D19-COUNTIFS('Access requests'!$C$2:$C$48,A19,'Access requests'!$M$2:$M$48,"Not needed") -> 8
A20: Azure DevOps (Boards) project admin | B20: =COUNTIF('Access requests'!$C$2:$C$48,A20) -> 2 | C20: =COUNTIFS('Access requests'!$C$2:$C$48,A20,'Access requests'!$K$2:$K$48,"P1*") -> 1 | D20: =COUNTIFS('Access requests'!$C$2:$C$48,A20,'Access requests'!$M$2:$M$48,"Granted") -> 0 | E20: =B20-D20-COUNTIFS('Access requests'!$C$2:$C$48,A20,'Access requests'!$M$2:$M$48,"Not needed") -> 2
A21: ServiceNow platform admin | B21: =COUNTIF('Access requests'!$C$2:$C$48,A21) -> 2 | C21: =COUNTIFS('Access requests'!$C$2:$C$48,A21,'Access requests'!$K$2:$K$48,"P1*") -> 0 | D21: =COUNTIFS('Access requests'!$C$2:$C$48,A21,'Access requests'!$M$2:$M$48,"Granted") -> 0 | E21: =B21-D21-COUNTIFS('Access requests'!$C$2:$C$48,A21,'Access requests'!$M$2:$M$48,"Not needed") -> 2
A22: Network / cloud platform team | B22: =COUNTIF('Access requests'!$C$2:$C$48,A22) -> 2 | C22: =COUNTIFS('Access requests'!$C$2:$C$48,A22,'Access requests'!$K$2:$K$48,"P1*") -> 1 | D22: =COUNTIFS('Access requests'!$C$2:$C$48,A22,'Access requests'!$M$2:$M$48,"Granted") -> 0 | E22: =B22-D22-COUNTIFS('Access requests'!$C$2:$C$48,A22,'Access requests'!$M$2:$M$48,"Not needed") -> 2
A23: Existing data/DevOps team (information) | B23: =COUNTIF('Access requests'!$C$2:$C$48,A23) -> 2 | C23: =COUNTIFS('Access requests'!$C$2:$C$48,A23,'Access requests'!$K$2:$K$48,"P1*") -> 1 | D23: =COUNTIFS('Access requests'!$C$2:$C$48,A23,'Access requests'!$M$2:$M$48,"Granted") -> 0 | E23: =B23-D23-COUNTIFS('Access requests'!$C$2:$C$48,A23,'Access requests'!$M$2:$M$48,"Not needed") -> 2
A24: Total | B24: =SUM(B14:B23) -> 47 | C24: =SUM(C14:C23) -> 35 | D24: =SUM(D14:D23) -> 0 | E24: =SUM(E14:E23) -> 47
A26: Phases
A27: P1: Start building: DEV, feature-branch testing, PR checks
A28: P2: First release to QA and UAT
A29: P3: First release to PROD
A31: Legend: ● = applies to that environment · yellow cells = for the admin to fill in

Sheet Access requests
A1: ID | B1: Area | C1: Granted by | D1: Principal / target | E1: DEV | F1: QA | G1: UAT | H1: PROD | I1: Permission / action requested | J1: Why it is needed | K1: Phase | L1: Notes | M1: Status | N1: Granted by (name) | O1: Date | P1: Admin comments
A2: GH-01 | B2: GitHub | C2: GitHub org owner | D2: Vamshi Singam (lead) | I2: Create private/internal repo <shell-org>/shell-data-platform; give the lead Admin role on it during setup | J2: New parallel process needs its own repo with ADF, Databricks and SQL projects side by side | K2: P1 | M2: Requested
A3: GH-02 | B3: GitHub | C3: GitHub org owner | D3: GitHub teams: developers, tech-leads, release-managers, qa-leads, uat-signoff | I3: Create or map teams (ideally synced from Entra groups); repo roles: developers = Write, tech-leads = Maintain, release-managers = Maintain | J3: Drives CODEOWNERS review and environment approvers | K3: P1 | M3: Requested
A4: GH-03 | B4: GitHub | C4: GitHub org owner | D4: Repo settings | I4: Allow squash merge only (disable merge commits and rebase merge); auto-delete head branches | J4: One PR = one commit on main, which makes releases selectable by PR number | K4: P1 | M4: Requested
A5: GH-04 | B5: GitHub | C5: GitHub org owner | D5: Ruleset on main | I5: Require PR; 1 approval from CODEOWNERS (tech-leads); dismiss stale approvals; require status check 'pr-validation'; require conversation resolution; block force-push and deletion; no bypass except org admins | J5: Gate 1: only reviewed, tested PRs reach main | K5: P1 | M5: Requested
A6: GH-05 | B6: GitHub | C6: GitHub org owner | D6: Ruleset on release/* branches and prod/* tags | I6: Restrict create/update/delete; bypass list = release-bot GitHub App only | J6: Nobody hand-edits a release branch or moves a production tag | K6: P2 | M6: Requested
A7: GH-06 | B7: GitHub | C7: GitHub org owner | D7: GitHub App 'shell-data-release-bot' | I7: Create app (Contents: read & write, Pull requests: read, Metadata: read), install on the repo only; give its App ID and private key to the lead for the 'release-cut' environment secret | J7: Cuts release/<id> branches and pushes prod/<id> tags past the ruleset in GH-05 | K7: P2 | M7: Requested
A8: GH-07 | B8: GitHub | C8: GitHub org owner | D8: GitHub Actions policy | I8: Enable Actions on the repo; allow actions: actions/*, azure/login, databricks/setup-cli, Azure/arm-deploy, Azure/sql-action (or allow 'verified creators') | J8: Workflows for validation, feature environments and releases | K8: P1 | M8: Requested
A9: GH-08 | B9: GitHub | C9: GitHub org owner | D9: Workflow permissions / OIDC | I9: Default GITHUB_TOKEN = read; workflows may request id-token: write (OIDC). Confirm no org policy blocks OIDC | J9: Passwordless sign-in to Azure with the existing managed identities | K9: P1 | M9: Requested
A10: GH-09 | B10: GitHub | C10: GitHub org owner | D10: GitHub Environments | E10: ● | F10: ● | G10: ● | H10: ● | I10: Create environments: dev-feature, dev, release-cut, qa, uat, prod. Required reviewers: qa = qa-leads, uat = uat-signoff, prod = release-managers. Deployment branches: dev-feature = feature/**, bugfix/**; dev = main; release-cut = main; qa/uat/prod = release/* | J10: Gates 3, 4 and 6 are environment approvals | K10: P1 | L10: Required reviewers on a private/internal repo need GitHub Enterprise (confirm plan, see OQ-07) | M10: Requested
A11: GH-10 | B11: GitHub | C11: GitHub org owner | D11: Environment secrets | G11: ● | H11: ● | I11: Store ServiceNow integration credentials as secrets in the 'prod' environment only (and 'uat' if the CR is checked before UAT) | J11: Gate 5 reads and updates the change request | K11: P3 | M11: Requested
A12: GH-11 | B12: GitHub | C12: GitHub org owner | D12: Third-party app access | E12: ● | I12: Approve the 'Azure Data Factory' and 'Databricks' GitHub apps / OAuth apps for the org (if OAuth app access restrictions are on) | J12: DEV factory Git mode and Databricks Git folders must read feature branches: this is what makes feature-branch testing possible | K12: P1 | L12: Blocking for feature testing | M12: Requested
A13: GH-12 | B13: GitHub | C13: GitHub org owner | D13: GitHub Actions runners | E13: ● | F13: ● | G13: ● | H13: ● | I13: GitHub-hosted runners if Azure endpoints are public. If ADF/SQL/Databricks are private: self-hosted runners in a VNet with line of sight (or GitHub-hosted runners with Azure private networking), registered to this repo | J13: Runners must reach SQL (DACPAC), Databricks and ARM endpoints | K13: P1 | L13: Depends on OQ-03 | M13: Requested
A14: ID-01 | B14: Identity | C14: Entra ID admin / identity owner | D14: Existing managed identities | E14: ● | F14: ● | G14: ● | H14: ● | I14: Confirm each identity we reuse is USER-assigned and give: name, client ID, object ID, resource group, tenant ID | J14: GitHub can only sign in through a user-assigned identity (or app registration); system-assigned identities (for example the factory's own) cannot take federated credentials | K14: P1 | L14: If they are system-assigned, request one user-assigned identity per environment instead (see OQ-04) | M14: Requested
A15: ID-02 | B15: Identity | C15: Entra ID admin / identity owner | D15: Deploy identity – DEV | E15: ● | I15: Add federated credentials: issuer https://token.actions.githubusercontent.com, audience api://AzureADTokenExchange, subjects repo:<shell-org>/shell-data-platform:environment:dev and …:environment:dev-feature | J15: deploy-dev and feature-env workflows | K15: P1 | L15: Needs Contributor/Owner on the identity to add | M15: Requested
A16: ID-03 | B16: Identity | C16: Entra ID admin / identity owner | D16: CI identity (read-only) – DEV | E16: ● | I16: Federated credential subject repo:<shell-org>/shell-data-platform:pull_request (a separate low-privilege identity is preferred; DEV deploy identity acceptable) | J16: pr-validation runs ADF validate and bundle validate against DEV | K16: P1 | M16: Requested
A17: ID-04 | B17: Identity | C17: Entra ID admin / identity owner | D17: Deploy identity – QA, UAT | F17: ● | G17: ● | I17: Federated credentials with subjects …:environment:qa and …:environment:uat (on each environment's identity) | J17: release workflow QA and UAT jobs | K17: P2 | M17: Requested
A18: ID-05 | B18: Identity | C18: Entra ID admin / identity owner | D18: Deploy identity – PROD | H18: ● | I18: Federated credential with subject …:environment:prod | J18: release workflow PROD job (runs only after release-manager approval) | K18: P3 | M18: Requested
A19: ID-06 | B19: Identity | C19: Entra ID admin / identity owner | D19: Entra security groups | I19: Create or confirm groups: grp-data-developers, grp-data-techleads, grp-data-qa, grp-data-uat-signoff, grp-data-release-managers | J19: Used for Azure RBAC, SQL, Databricks and GitHub team sync | K19: P1 | M19: Requested
A20: AZ-01 | B20: Azure RBAC | C20: Azure subscription owner (RBAC) | D20: Deploy identity – each env | E20: ● | F20: ● | G20: ● | H20: ● | I20: Data Factory Contributor on the resource group that holds that environment's factory | J20: ARM template deployment, stop/start triggers, delete removed pipelines | K20: P1 DEV · P2 QA/UAT · P3 PROD | M20: Requested
A21: AZ-02 | B21: Azure RBAC | C21: Azure subscription owner (RBAC) | D21: Deploy identity – DEV | E21: ● | I21: SQL DB Contributor on the DEV SQL logical server | J21: Create, copy and drop feature databases sqldb-etlcfg-ft-<story> | K21: P1 | L21: DEV only | M21: Requested
A22: AZ-03 | B22: Azure RBAC | C22: Azure subscription owner (RBAC) | D22: DEV SQL logical server | E22: ● | I22: Create elastic pool 'pool-etlcfg-feature' (small, e.g. GP 2 vCore or 50–100 eDTU) on the DEV server; name a cost owner | J22: Feature databases share one capped pool; nightly cleanup keeps it small | K22: P1 | L22: Sizing/cost decision (OQ-05) | M22: Requested
A23: AZ-04 | B23: Azure RBAC | C23: Azure subscription owner (RBAC) | D23: Deploy identity – each env | E23: ● | F23: ● | G23: ● | H23: ● | I23: Reader on the environment's data-platform resource group(s) | J23: Look up resource IDs, run ARM what-if | K23: P1 DEV · P2 QA/UAT · P3 PROD | M23: Requested
A24: AZ-05 | B24: Azure RBAC | C24: Azure subscription owner (RBAC) | D24: grp-data-developers | E24: ● | I24: Data Factory Contributor on the DEV factory only | J24: Author in Git mode and debug pipelines on feature branches | K24: P1 | L24: No write access to QA/UAT/PROD factories | M24: Requested
A25: AZ-06 | B25: Azure RBAC | C25: Azure subscription owner (RBAC) | D25: grp-data-developers | F25: ● | G25: ● | H25: ● | I25: Reader (or Data Factory monitoring via Reader) on QA/UAT/PROD factories | J25: Monitor runs without changing anything | K25: P2 | M25: Requested
A26: AZ-07 | B26: Azure RBAC | C26: Azure subscription owner (RBAC) | D26: Factory managed identity (existing) – each env | E26: ● | F26: ● | G26: ● | H26: ● | I26: Verify existing: Storage Blob Data Contributor on ADLS; Key Vault Secrets User on the Key Vault used by linked services | J26: Pipelines keep working after deployments | K26: P1 | L26: Verification only | M26: Requested
A27: SQL-01 | B27: Azure SQL | C27: Azure SQL server Entra admin | D27: Each config SQL logical server | E27: ● | F27: ● | G27: ● | H27: ● | I27: Confirm Microsoft Entra admin is set and Entra authentication is enabled; give server and database names | J27: Identities sign in without passwords | K27: P1 | M27: Requested
A28: SQL-02 | B28: Azure SQL | C28: Azure SQL server Entra admin | D28: Deploy identity – each env | E28: ● | F28: ● | G28: ● | H28: ● | I28: In the config DB: CREATE USER [<deploy-identity>] FROM EXTERNAL PROVIDER; ALTER ROLE db_owner ADD MEMBER [<deploy-identity>] | J28: DACPAC deploys schema, permissions and config rows | K28: P1 DEV · P2 QA/UAT · P3 PROD | L28: In DEV this user is copied into every feature DB automatically | M28: Requested
A29: SQL-03 | B29: Azure SQL | C29: Azure SQL server Entra admin | D29: Factory managed identity (existing) – each env | E29: ● | F29: ● | G29: ● | H29: ● | I29: Verify it is a user in the config DB with db_datareader, db_datawriter and EXECUTE | J29: ADF reads config and writes watermarks; copied into feature DBs automatically | K29: P1 | L29: Verification only | M29: Requested
A30: SQL-04 | B30: Azure SQL | C30: Azure SQL server Entra admin | D30: grp-data-developers | E30: ● | I30: db_datareader on sqldb-etlcfg-dev | J30: Inspect config; the feature-env workflow grants write access on each feature DB itself | K30: P1 | M30: Requested
A31: SQL-05 | B31: Azure SQL | C31: Network / cloud platform team | D31: Config SQL servers – network | E31: ● | F31: ● | G31: ● | H31: ● | I31: Allow the runners from GH-12 to reach port 1433: private endpoint + VNet runners, or firewall rule for static runner IPs | J31: DACPAC deployment and feature-DB setup | K31: P1 | L31: Depends on OQ-03 | M31: Requested
A32: DBX-01 | B32: Databricks | C32: Databricks account admin | D32: Deploy identity – each env | E32: ● | F32: ● | G32: ● | H32: ● | I32: Add the identity (by client ID) as a service principal in the Databricks account; assign it to that environment's workspace with 'Workspace access' | J32: Databricks CLI deploys asset bundles as this identity | K32: P1 DEV · P2 QA/UAT · P3 PROD | M32: Requested
A33: DBX-02 | B33: Databricks | C33: Databricks workspace admin / UC catalog owner | D33: Deploy identity – each env | E33: ● | F33: ● | G33: ● | H33: ● | I33: CAN MANAGE on the bundle root folder (e.g. /Workspace/Shared/shell-data); allowed to create jobs | J33: bundle deploy creates and updates jobs, notebooks and pipelines | K33: P1 DEV · P2 QA/UAT · P3 PROD | M33: Requested
A34: DBX-03 | B34: Databricks | C34: Databricks workspace admin / UC catalog owner | D34: Deploy identity – each env | E34: ● | F34: ● | G34: ● | H34: ● | I34: CAN USE on the job cluster policy, or serverless jobs enabled | J34: Jobs defined in the bundle can start compute | K34: P1 DEV · P2 QA/UAT · P3 PROD | L34: Depends on OQ-02 | M34: Requested
A35: DBX-04 | B35: Databricks | C35: Databricks workspace admin / UC catalog owner | D35: Deploy identity – each env | E35: ● | F35: ● | G35: ● | H35: ● | I35: If jobs run as an existing run-as service principal: 'Service Principal: User' role on that principal | J35: Bundle sets run_as on production jobs | K35: P2 | M35: Requested
A36: DBX-05 | B36: Databricks | C36: Databricks workspace admin / UC catalog owner | D36: Deploy identity – each env | E36: ● | F36: ● | G36: ● | H36: ● | I36: Unity Catalog on the environment catalog: USE CATALOG, USE SCHEMA, CREATE SCHEMA, CREATE TABLE, CREATE FUNCTION, CREATE VOLUME, MODIFY, SELECT (or ownership of bundle-managed schemas) | J36: Bundle-managed DDL and grants | K36: P1 DEV · P2 QA/UAT · P3 PROD | M36: Requested
A37: DBX-06 | B37: Databricks | C37: Databricks workspace admin / UC catalog owner | D37: Deploy identity – each env | E37: ● | F37: ● | G37: ● | H37: ● | I37: CAN USE on one SQL warehouse | J37: Run UC SQL steps during deployment | K37: P1 DEV · P2 QA/UAT · P3 PROD | M37: Requested
A38: DBX-07 | B38: Databricks | C38: Databricks workspace admin / UC catalog owner | D38: Factory managed identity (existing) – each env | E38: ● | F38: ● | G38: ● | H38: ● | I38: Verify it is a workspace service principal; give its client ID so the bundle grants it CAN MANAGE RUN on the jobs it triggers | J38: ADF triggers Databricks jobs after every deployment | K38: P1 | L38: Verification + information | M38: Requested
A39: DBX-08 | B39: Databricks | C39: Databricks workspace admin / UC catalog owner | D39: grp-data-developers | E39: ● | I39: DEV workspace access; serverless/cluster use; on dev catalog: USE CATALOG, CREATE SCHEMA (personal dev_<user> schemas) | J39: Developers deploy bundles in development mode: resources prefixed with their name, isolated per developer | K39: P1 | M39: Requested
A40: DBX-09 | B40: Databricks | C40: Databricks workspace admin / UC catalog owner | D40: DEV workspace – Git integration | E40: ● | I40: Allow Git folders to the GitHub org (add repo to the Git allowlist if restricted) | J40: Developers work on feature branches inside the workspace | K40: P1 | M40: Requested
...

Sheet Names to return
A1: Item | B1: DEV | C1: QA | D1: UAT | E1: PROD
A2: Tenant ID
A3: Subscription ID
A4: Resource group (data platform)
A5: Deploy identity name (user-assigned)
A6: Deploy identity client ID
A7: Data Factory name | B7: adf-…-dev
A8: Factory managed identity client ID
A9: SQL logical server
A10: Config database | B10: sqldb-etlcfg-dev
A11: Databricks workspace URL | B11: https://adb-….azuredatabricks.net
A12: Unity Catalog catalog
A13: SQL warehouse ID
A14: Self-hosted IR name (if any)
A15: Key Vault name
A17: Grey italic values in the DEV column are examples of the expected format; overwrite them.

Sheet Open questions
A1: ID | B1: Question | C1: What it affects | D1: Who can answer | E1: Answer
A2: OQ-01 | B2: Is each environment (DEV, QA, UAT, PROD) in its own subscription? Resource group and resource names per env? | C2: Scopes for every Azure role assignment | D2: Vamshi / platform team
A3: OQ-02 | B3: Is Databricks serverless (jobs and SQL) allowed, or must jobs use a cluster policy? | C3: DBX-03 and bundle job definitions | D3: Databricks admin
A4: OQ-03 | B4: Are ADF, Azure SQL and Databricks behind private endpoints? Which self-hosted integration runtimes exist? | C4: Runner choice (GH-12), SQL-05, ADF-02 | D4: Network team
A5: OQ-04 | B5: Are the managed identities we must reuse user-assigned or system-assigned? | C5: If system-assigned, GitHub cannot use them: new user-assigned identities are needed | D5: Entra admin
A6: OQ-05 | B6: Elastic pool size and cost owner for feature databases | C6: AZ-03 | D6: Budget owner
A7: OQ-06 | B7: How are Azure SQL scripts deployed today (SQL project/DACPAC, numbered scripts, other)? | C7: Decides the SQL project tooling; process stays the same | D7: Existing team
A8: OQ-07 | B8: Which GitHub plan does the org have (Enterprise Cloud?) | C8: Environment required reviewers on private/internal repos need GitHub Enterprise | D8: GitHub org owner
A9: OQ-08 | B9: ServiceNow: assignment group, change model, and whether CRs can be read/updated via API | C9: SN-01, SN-02 | D9: ServiceNow admin
